Workbook

Sheet 00_README
A1: PFI RM Lumbar - 36-month editable financial model
A3: Purpose | B3: Editable academic financial model for the lumbar MRI MVP business/economic chapter.
A4: Currency | B4: USD
A5: Horizon | B5: 36 months
A6: Scenario selector | B6: Cell 01_ASSUMPTIONS!B2 controls the active model.
A7: Scenarios | B7: Pesimista / Base / Optimista
A8: Important limitation | B8: All prices, costs, conversion, churn and demand assumptions are provisional and require external validation.
A9: Clinical/commercial status | B9: The model does not claim clinical adoption, reimbursability, procurement approval or productive availability.
A10: Editable sheets | B10: 01_ASSUMPTIONS, 02_PRICING, 04_CASH_FLOW
A11: Formula sheets | B11: 04_CASH_FLOW, 05_KPIS, 06_BREAK_EVEN, 07_SENSITIVITY
A12: Non-functional scope | B12: No LaTeX update, no code change, no macros.
A13: Validation note | B13: Generated and checked programmatically; open in Excel/LibreOffice to recalculate after manual edits.
A14: Repository note | B14: This workbook is documentation/business-model evidence only.

Sheet 01_ASSUMPTIONS
A1: Category | B1: Variable | C1: Pesimista | D1: Base | E1: Optimista | F1: Unit | G1: Type | H1: Justification | I1: Source / pending | J1: Active value
A2: Active scenario | B2: Base | D2: Monthly discount rate | E2: =(1+INDEX($J$5:$J$39,MATCH("annual_discount_rate",$B$5:$B$39,0)))^(1/12)-1
A4: Category | B4: Variable | C4: Pesimista | D4: Base | E4: Optimista | F4: Unit | G4: Type | H4: Justification | I4: Source / pending | J4: Active value
A5: General | B5: horizon_months | C5: 36 | D5: 36 | E5: 36 | F5: months | G5: input | H5: Model horizon requested for the business plan. | I5: Defined by scope; validate with thesis committee. | J5: =CHOOSE(MATCH($B$2,$C$4:$E$4,0),C5,D5,E5)
A6: General | B6: annual_discount_rate | C6: 0.35 | D6: 0.25 | E6: 0.18 | F6: % | G6: input | H6: Risk-adjusted prototype-stage discount rate. | I6: Pending local WACC/risk benchmark. | J6: =CHOOSE(MATCH($B$2,$C$4:$E$4,0),C6,D6,E6)
A7: General | B7: fx_usd_ars | C7: 1000 | D7: 1000 | E7: 1000 | F7: ARS/USD | G7: memo | H7: Reference FX only; workbook currency is USD. | I7: Pending finance source at decision date. | J7: =CHOOSE(MATCH($B$2,$C$4:$E$4,0),C7,D7,E7)
A8: Pricing | B8: starter_fee | C8: 400 | D8: 600 | E8: 900 | F8: USD/month | G8: input | H8: Entry institutional pilot package. | I8: Pending willingness-to-pay interviews. | J8: =CHOOSE(MATCH($B$2,$C$4:$E$4,0),C8,D8,E8)
A9: Pricing | B9: starter_included_studies | C9: 80 | D9: 120 | E9: 180 | F9: studies/month | G9: input | H9: Included volume for entry package. | I9: Pending real usage distribution. | J9: =CHOOSE(MATCH($B$2,$C$4:$E$4,0),C9,D9,E9)
A10: Pricing | B10: starter_overage_fee | C10: 6 | D10: 8 | E10: 10 | F10: USD/study | G10: input | H10: Overage per processed study. | I10: Pending commercial validation. | J10: =CHOOSE(MATCH($B$2,$C$4:$E$4,0),C10,D10,E10)
A11: Pricing | B11: professional_fee | C11: 1100 | D11: 1600 | E11: 2300 | F11: USD/month | G11: input | H11: Mid-tier institutional subscription. | I11: Pending willingness-to-pay interviews. | J11: =CHOOSE(MATCH($B$2,$C$4:$E$4,0),C11,D11,E11)
A12: Pricing | B12: professional_included_studies | C12: 300 | D12: 500 | E12: 750 | F12: studies/month | G12: input | H12: Included volume for mid-tier package. | I12: Pending real usage distribution. | J12: =CHOOSE(MATCH($B$2,$C$4:$E$4,0),C12,D12,E12)
A13: Pricing | B13: professional_overage_fee | C13: 4.5 | D13: 6 | E13: 8 | F13: USD/study | G13: input | H13: Mid-tier overage price. | I13: Pending commercial validation. | J13: =CHOOSE(MATCH($B$2,$C$4:$E$4,0),C13,D13,E13)
A14: Pricing | B14: enterprise_fee | C14: 3000 | D14: 4500 | E14: 7000 | F14: USD/month | G14: input | H14: Large-center subscription. | I14: Pending enterprise procurement validation. | J14: =CHOOSE(MATCH($B$2,$C$4:$E$4,0),C14,D14,E14)
A15: Pricing | B15: enterprise_included_studies | C15: 900 | D15: 1500 | E15: 2400 | F15: studies/month | G15: input | H15: Included volume for large-center package. | I15: Pending real usage distribution. | J15: =CHOOSE(MATCH($B$2,$C$4:$E$4,0),C15,D15,E15)
A16: Pricing | B16: enterprise_overage_fee | C16: 3 | D16: 4 | E16: 5 | F16: USD/study | G16: input | H16: Large-tier overage price. | I16: Pending commercial validation. | J16: =CHOOSE(MATCH($B$2,$C$4:$E$4,0),C16,D16,E16)
... A39: Investment | B39: launch_setup | C39: 500 | D39: 2500 | E39: 7000 | F39: USD upfront | G39: input | H39: Launch material, legal, onboarding setup. | I39: Pending launch plan. | J39: =CHOOSE(MATCH($B$2,$C$4:$E$4,0),C39,D39,E39)

Sheet 02_PRICING
A1: Tier | B1: Monthly fee | C1: Included studies | D1: Overage fee | E1: Target user | F1: Validation status
A2: Starter | B2: =INDEX('01_ASSUMPTIONS'!$J$5:$J$39,MATCH("starter_fee",'01_ASSUMPTIONS'!$B$5:$B$39,0)) | C2: =INDEX('01_ASSUMPTIONS'!$J$5:$J$39,MATCH("starter_included_studies",'01_ASSUMPTIONS'!$B$5:$B$39,0)) | D2: =INDEX('01_ASSUMPTIONS'!$J$5:$J$39,MATCH("starter_overage_fee",'01_ASSUMPTIONS'!$B$5:$B$39,0)) | E2: Small pilot / low-volume center | F2: Provisional
A3: Professional | B3: =INDEX('01_ASSUMPTIONS'!$J$5:$J$39,MATCH("professional_fee",'01_ASSUMPTIONS'!$B$5:$B$39,0)) | C3: =INDEX('01_ASSUMPTIONS'!$J$5:$J$39,MATCH("professional_included_studies",'01_ASSUMPTIONS'!$B$5:$B$39,0)) | D3: =INDEX('01_ASSUMPTIONS'!$J$5:$J$39,MATCH("professional_overage_fee",'01_ASSUMPTIONS'!$B$5:$B$39,0)) | E3: Clinical center / teaching hospital | F3: Provisional
A4: Enterprise | B4: =INDEX('01_ASSUMPTIONS'!$J$5:$J$39,MATCH("enterprise_fee",'01_ASSUMPTIONS'!$B$5:$B$39,0)) | C4: =INDEX('01_ASSUMPTIONS'!$J$5:$J$39,MATCH("enterprise_included_studies",'01_ASSUMPTIONS'!$B$5:$B$39,0)) | D4: =INDEX('01_ASSUMPTIONS'!$J$5:$J$39,MATCH("enterprise_overage_fee",'01_ASSUMPTIONS'!$B$5:$B$39,0)) | E4: Large institution / network | F4: Provisional

Sheet 04_CASH_FLOW
A1: Month | B1: Active customers Starter | C1: Active customers Professional | D1: Active customers Enterprise | E1: Total customers | F1: Studies Starter | G1: Studies Professional | H1: Studies Enterprise | I1: Total studies | J1: Subscription revenue | K1: Overage revenue | L1: Total revenue | M1: Cloud cost | N1: Storage cost | O1: AI processing cost | P1: Variable support | Q1: Total variable costs | R1: Fixed infrastructure | S1: Maintenance | T1: Base support | U1: Admin | V1: Commercial/marketing | W1: Other fixed | X1: Total fixed costs | Y1: EBITDA / operating result | Z1: Initial investment | AA1: Net cash flow | AB1: Discount factor | AC1: Discounted cash flow | AD1: Cumulative cash flow | AE1: Operating break-even flag | AF1: Payback flag
A2: =1 | B2: =INDEX('01_ASSUMPTIONS'!$J$5:$J$39,MATCH("starter_initial_customers",'01_ASSUMPTIONS'!$B$5:$B$39,0))+INDEX('01_ASSUMPTIONS'!$J$5:$J$39,MATCH("starter_monthly_acquisition",'01_ASSUMPTIONS'!$B$5:$B$39,0)) | C2: =INDEX('01_ASSUMPTIONS'!$J$5:$J$39,MATCH("professional_initial_customers",'01_ASSUMPTIONS'!$B$5:$B$39,0))+INDEX('01_ASSUMPTIONS'!$J$5:$J$39,MATCH("professional_monthly_acquisition",'01_ASSUMPTIONS'!$B$5:$B$39,0)) | D2: =INDEX('01_ASSUMPTIONS'!$J$5:$J$39,MATCH("enterprise_initial_customers",'01_ASSUMPTIONS'!$B$5:$B$39,0))+INDEX('01_ASSUMPTIONS'!$J$5:$J$39,MATCH("enterprise_monthly_acquisition",'01_ASSUMPTIONS'!$B$5:$B$39,0)) | E2: =SUM(B2:D2) | F2: =B2*INDEX('01_ASSUMPTIONS'!$J$5:$J$39,MATCH("starter_studies_per_customer",'01_ASSUMPTIONS'!$B$5:$B$39,0)) | G2: =C2*INDEX('01_ASSUMPTIONS'!$J$5:$J$39,MATCH("professional_studies_per_customer",'01_ASSUMPTIONS'!$B$5:$B$39,0)) | H2: =D2*INDEX('01_ASSUMPTIONS'!$J$5:$J$39,MATCH("enterprise_studies_per_customer",'01_ASSUMPTIONS'!$B$5:$B$39,0)) | I2: =SUM(F2:H2) | J2: =B2*INDEX('01_ASSUMPTIONS'!$J$5:$J$39,MATCH("starter_fee",'01_ASSUMPTIONS'!$B$5:$B$39,0))+C2*INDEX('01_ASSUMPTIONS'!$J$5:$J$39,MATCH("professional_fee",'01_ASSUMPTIONS'!$B$5:$B$39,0))+D2*INDEX('01_ASSUMPTIONS'!$J$5:$J$39,MATCH("enterprise_fee",'01_ASSUMPTIONS'!$B$5:$B$39,0)) | K2: =MAX(F2-B2*INDEX('01_ASSUMPTIONS'!$J$5:$J$39,MATCH("starter_included_studies",'01_ASSUMPTIONS'!$B$5:$B$39,0)),0)*INDEX('01_ASSUMPTIONS'!$J$5:$J$39,MATCH("starter_overage_fee",'01_ASSUMPTIONS'!$B$5:$B$39,0))+MAX(G2-C2*INDEX('01_ASSUMPTIONS'!$J$5:$J$39,MATCH("professional_included_studies",'01_ASSUMPTIONS'!$B$5:$B$39,0)),0)*INDEX('01_ASSUMPTIONS'!$J$5:$J$39,MATCH("professional_overage_fee",'01_ASSUMPTIONS'!$B$5:$B$39,0))+MAX(H2-D2*INDEX('01_ASSUMPTIONS'!$J$5:$J$39,MATCH("enterprise_included_studies",'01_ASSUMPTIONS'!$B$5:$B$39,0)),0)*INDEX('01_ASSUMPTIONS'!$J$5:$J$39,MATCH("enterprise_overage_fee",'01_ASSUMPTIONS'!$B$5:$B$39,0)) | L2: =J2+K2 | M2: =I2*INDEX('01_ASSUMPTIONS'!$J$5:$J$39,MATCH("cloud_cost_per_study",'01_ASSUMPTIONS'!$B$5:$B$39,0)) | N2: =I2*INDEX('01_ASSUMPTIONS'!$J$5:$J$39,MATCH("storage_cost_per_study",'01_ASSUMPTIONS'!$B$5:$B$39,0)) | O2: =I2*INDEX('01_ASSUMPTIONS'!$J$5:$J$39,MATCH("ai_processing_cost_per_study",'01_ASSUMPTIONS'!$B$5:$B$39,0)) | P2: =E2*INDEX('01_ASSUMPTIONS'!$J$5:$J$39,MATCH("variable_support_per_customer",'01_ASSUMPTIONS'!$B$5:$B$39,0)) | Q2: =SUM(M2:P2) | R2: =INDEX('01_ASSUMPTIONS'!$J$5:$J$39,MATCH("fixed_infra",'01_ASSUMPTIONS'!$B$5:$B$39,0)) | S2: =INDEX('01_ASSUMPTIONS'!$J$5:$J$39,MATCH("software_maintenance",'01_ASSUMPTIONS'!$B$5:$B$39,0)) | T2: =INDEX('01_ASSUMPTIONS'!$J$5:$J$39,MATCH("base_support",'01_ASSUMPTIONS'!$B$5:$B$39,0)) | U2: =INDEX('01_ASSUMPTIONS'!$J$5:$J$39,MATCH("admin",'01_ASSUMPTIONS'!$B$5:$B$39,0)) | V2: =INDEX('01_ASSUMPTIONS'!$J$5:$J$39,MATCH("commercial_marketing",'01_ASSUMPTIONS'!$B$5:$B$39,0)) | W2: =INDEX('01_ASSUMPTIONS'!$J$5:$J$39,MATCH("other_fixed",'01_ASSUMPTIONS'!$B$5:$B$39,0)) | X2: =SUM(R2:W2) | Y2: =L2-Q2-X2 | Z2: =INDEX('01_ASSUMPTIONS'!$J$5:$J$39,MATCH("development_investment",'01_ASSUMPTIONS'!$B$5:$B$39,0))+INDEX('01_ASSUMPTIONS'!$J$5:$J$39,MATCH("cloud_setup",'01_ASSUMPTIONS'!$B$5:$B$39,0))+INDEX('01_ASSUMPTIONS'!$J$5:$J$39,MATCH("launch_setup",'01_ASSUMPTIONS'!$B$5:$B$39,0)) | AA2: =Y2-Z2 | AB2: =1/(1+'01_ASSUMPTIONS'!$E$2)^A2 | AC2: =AA2*AB2 | AD2: =AA2 | AE2: =IF(Y2>=0,"Yes","No") | AF2: =IF(AD2>=0,"Yes","No")
A3: =2 | B3: =B2*(1-INDEX('01_ASSUMPTIONS'!$J$5:$J$39,MATCH("monthly_churn",'01_ASSUMPTIONS'!$B$5:$B$39,0)))+INDEX('01_ASSUMPTIONS'!$J$5:$J$39,MATCH("starter_monthly_acquisition",'01_ASSUMPTIONS'!$B$5:$B$39,0)) | C3: =C2*(1-INDEX('01_ASSUMPTIONS'!$J$5:$J$39,MATCH("monthly_churn",'01_ASSUMPTIONS'!$B$5:$B$39,0)))+INDEX('01_ASSUMPTIONS'!$J$5:$J$39,MATCH("professional_monthly_acquisition",'01_ASSUMPTIONS'!$B$5:$B$39,0)) | D3: =D2*(1-INDEX('01_ASSUMPTIONS'!$J$5:$J$39,MATCH("monthly_churn",'01_ASSUMPTIONS'!$B$5:$B$39,0)))+INDEX('01_ASSUMPTIONS'!$J$5:$J$39,MATCH("enterprise_monthly_acquisition",'01_ASSUMPTIONS'!$B$5:$B$39,0)) | E3: =SUM(B3:D3) | F3: =B3*INDEX('01_ASSUMPTIONS'!$J$5:$J$39,MATCH("starter_studies_per_customer",'01_ASSUMPTIONS'!$B$5:$B$39,0)) | G3: =C3*INDEX('01_ASSUMPTIONS'!$J$5:$J$39,MATCH("professional_studies_per_customer",'01_ASSUMPTIONS'!$B$5:$B$39,0)) | H3: =D3*INDEX('01_ASSUMPTIONS'!$J$5:$J$39,MATCH("enterprise_studies_per_customer",'01_ASSUMPTIONS'!$B$5:$B$39,0)) | I3: =SUM(F3:H3) | J3: =B3*INDEX('01_ASSUMPTIONS'!$J$5:$J$39,MATCH("starter_fee",'01_ASSUMPTIONS'!$B$5:$B$39,0))+C3*INDEX('01_ASSUMPTIONS'!$J$5:$J$39,MATCH("professional_fee",'01_ASSUMPTIONS'!$B$5:$B$39,0))+D3*INDEX('01_ASSUMPTIONS'!$J$5:$J$39,MATCH("enterprise_fee",'01_ASSUMPTIONS'!$B$5:$B$39,0)) | K3: =MAX(F3-B3*INDEX('01_ASSUMPTIONS'!$J$5:$J$39,MATCH("starter_included_studies",'01_ASSUMPTIONS'!$B$5:$B$39,0)),0)*INDEX('01_ASSUMPTIONS'!$J$5:$J$39,MATCH("starter_overage_fee",'01_ASSUMPTIONS'!$B$5:$B$39,0))+MAX(G3-C3*INDEX('01_ASSUMPTIONS'!$J$5:$J$39,MATCH("professional_included_studies",'01_ASSUMPTIONS'!$B$5:$B$39,0)),0)*INDEX('01_ASSUMPTIONS'!$J$5:$J$39,MATCH("professional_overage_fee",'01_ASSUMPTIONS'!$B$5:$B$39,0))+MAX(H3-D3*INDEX('01_ASSUMPTIONS'!$J$5:$J$39,MATCH("enterprise_included_studies",'01_ASSUMPTIONS'!$B$5:$B$39,0)),0)*INDEX('01_ASSUMPTIONS'!$J$5:$J$39,MATCH("enterprise_overage_fee",'01_ASSUMPTIONS'!$B$5:$B$39,0)) | L3: =J3+K3 | M3: =I3*INDEX('01_ASSUMPTIONS'!$J$5:$J$39,MATCH("cloud_cost_per_study",'01_ASSUMPTIONS'!$B$5:$B$39,0)) | N3: =I3*INDEX('01_ASSUMPTIONS'!$J$5:$J$39,MATCH("storage_cost_per_study",'01_ASSUMPTIONS'!$B$5:$B$39,0)) | O3: =I3*INDEX('01_ASSUMPTIONS'!$J$5:$J$39,MATCH("ai_processing_cost_per_study",'01_ASSUMPTIONS'!$B$5:$B$39,0)) | P3: =E3*INDEX('01_ASSUMPTIONS'!$J$5:$J$39,MATCH("variable_support_per_customer",'01_ASSUMPTIONS'!$B$5:$B$39,0)) | Q3: =SUM(M3:P3) | R3: =INDEX('01_ASSUMPTIONS'!$J$5:$J$39,MATCH("fixed_infra",'01_ASSUMPTIONS'!$B$5:$B$39,0)) | S3: =INDEX('01_ASSUMPTIONS'!$J$5:$J$39,MATCH("software_maintenance",'01_ASSUMPTIONS'!$B$5:$B$39,0)) | T3: =INDEX('01_ASSUMPTIONS'!$J$5:$J$39,MATCH("base_support",'01_ASSUMPTIONS'!$B$5:$B$39,0)) | U3: =INDEX('01_ASSUMPTIONS'!$J$5:$J$39,MATCH("admin",'01_ASSUMPTIONS'!$B$5:$B$39,0)) | V3: =INDEX('01_ASSUMPTIONS'!$J$5:$J$39,MATCH("commercial_marketing",'01_ASSUMPTIONS'!$B$5:$B$39,0)) | W3: =INDEX('01_ASSUMPTIONS'!$J$5:$J$39,MATCH("other_fixed",'01_ASSUMPTIONS'!$B$5:$B$39,0)) | X3: =SUM(R3:W3) | Y3: =L3-Q3-X3 | Z3: =0 | AA3: =Y3-Z3 | AB3: =1/(1+'01_ASSUMPTIONS'!$E$2)^A3 | AC3: =AA3*AB3 | AD3: =AD2+AA3 | AE3: =IF(Y3>=0,"Yes","No") | AF3: =IF(AD3>=0,"Yes","No")
A4: =3 | B4: =B3*(1-INDEX('01_ASSUMPTIONS'!$J$5:$J$39,MATCH("monthly_churn",'01_ASSUMPTIONS'!$B$5:$B$39,0)))+INDEX('01_ASSUMPTIONS'!$J$5:$J$39,MATCH("starter_monthly_acquisition",'01_ASSUMPTIONS'!$B$5:$B$39,0)) | C4: =C3*(1-INDEX('01_ASSUMPTIONS'!$J$5:$J$39,MATCH("monthly_churn",'01_ASSUMPTIONS'!$B$5:$B$39,0)))+INDEX('01_ASSUMPTIONS'!$J$5:$J$39,MATCH("professional_monthly_acquisition",'01_ASSUMPTIONS'!$B$5:$B$39,0)) | D4: =D3*(1-INDEX('01_ASSUMPTIONS'!$J$5:$J$39,MATCH("monthly_churn",'01_ASSUMPTIONS'!$B$5:$B$39,0)))+INDEX('01_ASSUMPTIONS'!$J$5:$J$39,MATCH("enterprise_monthly_acquisition",'01_ASSUMPTIONS'!$B$5:$B$39,0)) | E4: =SUM(B4:D4) | F4: =B4*INDEX('01_ASSUMPTIONS'!$J$5:$J$39,MATCH("starter_studies_per_customer",'01_ASSUMPTIONS'!$B$5:$B$39,0)) | G4: =C4*INDEX('01_ASSUMPTIONS'!$J$5:$J$39,MATCH("professional_studies_per_customer",'01_ASSUMPTIONS'!$B$5:$B$39,0)) | H4: =D4*INDEX('01_ASSUMPTIONS'!$J$5:$J$39,MATCH("enterprise_studies_per_customer",'01_ASSUMPTIONS'!$B$5:$B$39,0)) | I4: =SUM(F4:H4) | J4: =B4*INDEX('01_ASSUMPTIONS'!$J$5:$J$39,MATCH("starter_fee",'01_ASSUMPTIONS'!$B$5:$B$39,0))+C4*INDEX('01_ASSUMPTIONS'!$J$5:$J$39,MATCH("professional_fee",'01_ASSUMPTIONS'!$B$5:$B$39,0))+D4*INDEX('01_ASSUMPTIONS'!$J$5:$J$39,MATCH("enterprise_fee",'01_ASSUMPTIONS'!$B$5:$B$39,0)) | K4: =MAX(F4-B4*INDEX('01_ASSUMPTIONS'!$J$5:$J$39,MATCH("starter_included_studies",'01_ASSUMPTIONS'!$B$5:$B$39,0)),0)*INDEX('01_ASSUMPTIONS'!$J$5:$J$39,MATCH("starter_overage_fee",'01_ASSUMPTIONS'!$B$5:$B$39,0))+MAX(G4-C4*INDEX('01_ASSUMPTIONS'!$J$5:$J$39,MATCH("professional_included_studies",'01_ASSUMPTIONS'!$B$5:$B$39,0)),0)*INDEX('01_ASSUMPTIONS'!$J$5:$J$39,MATCH("professional_overage_fee",'01_ASSUMPTIONS'!$B$5:$B$39,0))+MAX(H4-D4*INDEX('01_ASSUMPTIONS'!$J$5:$J$39,MATCH("enterprise_included_studies",'01_ASSUMPTIONS'!$B$5:$B$39,0)),0)*INDEX('01_ASSUMPTIONS'!$J$5:$J$39,MATCH("enterprise_overage_fee",'01_ASSUMPTIONS'!$B$5:$B$39,0)) | L4: =J4+K4 | M4: =I4*INDEX('01_ASSUMPTIONS'!$J$5:$J$39,MATCH("cloud_cost_per_study",'01_ASSUMPTIONS'!$B$5:$B$39,0)) | N4: =I4*INDEX('01_ASSUMPTIONS'!$J$5:$J$39,MATCH("storage_cost_per_study",'01_ASSUMPTIONS'!$B$5:$B$39,0)) | O4: =I4*INDEX('01_ASSUMPTIONS'!$J$5:$J$39,MATCH("ai_processing_cost_per_study",'01_ASSUMPTIONS'!$B$5:$B$39,0)) | P4: =E4*INDEX('01_ASSUMPTIONS'!$J$5:$J$39,MATCH("variable_support_per_customer",'01_ASSUMPTIONS'!$B$5:$B$39,0)) | Q4: =SUM(M4:P4) | R4: =INDEX('01_ASSUMPTIONS'!$J$5:$J$39,MATCH("fixed_infra",'01_ASSUMPTIONS'!$B$5:$B$39,0)) | S4: =INDEX('01_ASSUMPTIONS'!$J$5:$J$39,MATCH("software_maintenance",'01_ASSUMPTIONS'!$B$5:$B$39,0)) | T4: =INDEX('01_ASSUMPTIONS'!$J$5:$J$39,MATCH("base_support",'01_ASSUMPTIONS'!$B$5:$B$39,0)) | U4: =INDEX('01_ASSUMPTIONS'!$J$5:$J$39,MATCH("admin",'01_ASSUMPTIONS'!$B$5:$B$39,0)) | V4: =INDEX('01_ASSUMPTIONS'!$J$5:$J$39,MATCH("commercial_marketing",'01_ASSUMPTIONS'!$B$5:$B$39,0)) | W4: =INDEX('01_ASSUMPTIONS'!$J$5:$J$39,MATCH("other_fixed",'01_ASSUMPTIONS'!$B$5:$B$39,0)) | X4: =SUM(R4:W4) | Y4: =L4-Q4-X4 | Z4: =0 | AA4: =Y4-Z4 | AB4: =1/(1+'01_ASSUMPTIONS'!$E$2)^A4 | AC4: =AA4*AB4 | AD4: =AD3+AA4 | AE4: =IF(Y4>=0,"Yes","No") | AF4: =IF(AD4>=0,"Yes","No")
A5: =4 | B5: =B4*(1-INDEX('01_ASSUMPTIONS'!$J$5:$J$39,MATCH("monthly_churn",'01_ASSUMPTIONS'!$B$5:$B$39,0)))+INDEX('01_ASSUMPTIONS'!$J$5:$J$39,MATCH("starter_monthly_acquisition",'01_ASSUMPTIONS'!$B$5:$B$39,0)) | C5: =C4*(1-INDEX('01_ASSUMPTIONS'!$J$5:$J$39,MATCH("monthly_churn",'01_ASSUMPTIONS'!$B$5:$B$39,0)))+INDEX('01_ASSUMPTIONS'!$J$5:$J$39,MATCH("professional_monthly_acquisition",'01_ASSUMPTIONS'!$B$5:$B$39,0)) | D5: =D4*(1-INDEX('01_ASSUMPTIONS'!$J$5:$J$39,MATCH("monthly_churn",'01_ASSUMPTIONS'!$B$5:$B$39,0)))+INDEX('01_ASSUMPTIONS'!$J$5:$J$39,MATCH("enterprise_monthly_acquisition",'01_ASSUMPTIONS'!$B$5:$B$39,0)) | E5: =SUM(B5:D5) | F5: =B5*INDEX('01_ASSUMPTIONS'!$J$5:$J$39,MATCH("starter_studies_per_customer",'01_ASSUMPTIONS'!$B$5:$B$39,0)) | G5: =C5*INDEX('01_ASSUMPTIONS'!$J$5:$J$39,MATCH("professional_studies_per_customer",'01_ASSUMPTIONS'!$B$5:$B$39,0)) | H5: =D5*INDEX('01_ASSUMPTIONS'!$J$5:$J$39,MATCH("enterprise_studies_per_customer",'01_ASSUMPTIONS'!$B$5:$B$39,0)) | I5: =SUM(F5:H5) | J5: =B5*INDEX('01_ASSUMPTIONS'!$J$5:$J$39,MATCH("starter_fee",'01_ASSUMPTIONS'!$B$5:$B$39,0))+C5*INDEX('01_ASSUMPTIONS'!$J$5:$J$39,MATCH("professional_fee",'01_ASSUMPTIONS'!$B$5:$B$39,0))+D5*INDEX('01_ASSUMPTIONS'!$J$5:$J$39,MATCH("enterprise_fee",'01_ASSUMPTIONS'!$B$5:$B$39,0)) | K5: =MAX(F5-B5*INDEX('01_ASSUMPTIONS'!$J$5:$J$39,MATCH("starter_included_studies",'01_ASSUMPTIONS'!$B$5:$B$39,0)),0)*INDEX('01_ASSUMPTIONS'!$J$5:$J$39,MATCH("starter_overage_fee",'01_ASSUMPTIONS'!$B$5:$B$39,0))+MAX(G5-C5*INDEX('01_ASSUMPTIONS'!$J$5:$J$39,MATCH("professional_included_studies",'01_ASSUMPTIONS'!$B$5:$B$39,0)),0)*INDEX('01_ASSUMPTIONS'!$J$5:$J$39,MATCH("professional_overage_fee",'01_ASSUMPTIONS'!$B$5:$B$39,0))+MAX(H5-D5*INDEX('01_ASSUMPTIONS'!$J$5:$J$39,MATCH("enterprise_included_studies",'01_ASSUMPTIONS'!$B$5:$B$39,0)),0)*INDEX('01_ASSUMPTIONS'!$J$5:$J$39,MATCH("enterprise_overage_fee",'01_ASSUMPTIONS'!$B$5:$B$39,0)) | L5: =J5+K5 | M5: =I5*INDEX('01_ASSUMPTIONS'!$J$5:$J$39,MATCH("cloud_cost_per_study",'01_ASSUMPTIONS'!$B$5:$B$39,0)) | N5: =I5*INDEX('01_ASSUMPTIONS'!$J$5:$J$39,MATCH("storage_cost_per_study",'01_ASSUMPTIONS'!$B$5:$B$39,0)) | O5: =I5*INDEX('01_ASSUMPTIONS'!$J$5:$J$39,MATCH("ai_processing_cost_per_study",'01_ASSUMPTIONS'!$B$5:$B$39,0)) | P5: =E5*INDEX('01_ASSUMPTIONS'!$J$5:$J$39,MATCH("variable_support_per_customer",'01_ASSUMPTIONS'!$B$5:$B$39,0)) | Q5: =SUM(M5:P5) | R5: =INDEX('01_ASSUMPTIONS'!$J$5:$J$39,MATCH("fixed_infra",'01_ASSUMPTIONS'!$B$5:$B$39,0)) | S5: =INDEX('01_ASSUMPTIONS'!$J$5:$J$39,MATCH("software_maintenance",'01_ASSUMPTIONS'!$B$5:$B$39,0)) | T5: =INDEX('01_ASSUMPTIONS'!$J$5:$J$39,MATCH("base_support",'01_ASSUMPTIONS'!$B$5:$B$39,0)) | U5: =INDEX('01_ASSUMPTIONS'!$J$5:$J$39,MATCH("admin",'01_ASSUMPTIONS'!$B$5:$B$39,0)) | V5: =INDEX('01_ASSUMPTIONS'!$J$5:$J$39,MATCH("commercial_marketing",'01_ASSUMPTIONS'!$B$5:$B$39,0)) | W5: =INDEX('01_ASSUMPTIONS'!$J$5:$J$39,MATCH("other_fixed",'01_ASSUMPTIONS'!$B$5:$B$39,0)) | X5: =SUM(R5:W5) | Y5: =L5-Q5-X5 | Z5: =0 | AA5: =Y5-Z5 | AB5: =1/(1+'01_ASSUMPTIONS'!$E$2)^A5 | AC5: =AA5*AB5 | AD5: =AD4+AA5 | AE5: =IF(Y5>=0,"Yes","No") | AF5: =IF(AD5>=0,"Yes","No")
A6: =5 | B6: =B5*(1-INDEX('01_ASSUMPTIONS'!$J$5:$J$39,MATCH("monthly_churn",'01_ASSUMPTIONS'!$B$5:$B$39,0)))+INDEX('01_ASSUMPTIONS'!$J$5:$J$39,MATCH("starter_monthly_acquisition",'01_ASSUMPTIONS'!$B$5:$B$39,0)) | C6: =C5*(1-INDEX('01_ASSUMPTIONS'!$J$5:$J$39,MATCH("monthly_churn",'01_ASSUMPTIONS'!$B$5:$B$39,0)))+INDEX('01_ASSUMPTIONS'!$J$5:$J$39,MATCH("professional_monthly_acquisition",'01_ASSUMPTIONS'!$B$5:$B$39,0)) | D6: =D5*(1-INDEX('01_ASSUMPTIONS'!$J$5:$J$39,MATCH("monthly_churn",'01_ASSUMPTIONS'!$B$5:$B$39,0)))+INDEX('01_ASSUMPTIONS'!$J$5:$J$39,MATCH("enterprise_monthly_acquisition",'01_ASSUMPTIONS'!$B$5:$B$39,0)) | E6: =SUM(B6:D6) | F6: =B6*INDEX('01_ASSUMPTIONS'!$J$5:$J$39,MATCH("starter_studies_per_customer",'01_ASSUMPTIONS'!$B$5:$B$39,0)) | G6: =C6*INDEX('01_ASSUMPTIONS'!$J$5:$J$39,MATCH("professional_studies_per_customer",'01_ASSUMPTIONS'!$B$5:$B$39,0)) | H6: =D6*INDEX('01_ASSUMPTIONS'!$J$5:$J$39,MATCH("enterprise_studies_per_customer",'01_ASSUMPTIONS'!$B$5:$B$39,0)) | I6: =SUM(F6:H6) | J6: =B6*INDEX('01_ASSUMPTIONS'!$J$5:$J$39,MATCH("starter_fee",'01_ASSUMPTIONS'!$B$5:$B$39,0))+C6*INDEX('01_ASSUMPTIONS'!$J$5:$J$39,MATCH("professional_fee",'01_ASSUMPTIONS'!$B$5:$B$39,0))+D6*INDEX('01_ASSUMPTIONS'!$J$5:$J$39,MATCH("enterprise_fee",'01_ASSUMPTIONS'!$B$5:$B$39,0)) | K6: =MAX(F6-B6*INDEX('01_ASSUMPTIONS'!$J$5:$J$39,MATCH("starter_included_studies",'01_ASSUMPTIONS'!$B$5:$B$39,0)),0)*INDEX('01_ASSUMPTIONS'!$J$5:$J$39,MATCH("starter_overage_fee",'01_ASSUMPTIONS'!$B$5:$B$39,0))+MAX(G6-C6*INDEX('01_ASSUMPTIONS'!$J$5:$J$39,MATCH("professional_included_studies",'01_ASSUMPTIONS'!$B$5:$B$39,0)),0)*INDEX('01_ASSUMPTIONS'!$J$5:$J$39,MATCH("professional_overage_fee",'01_ASSUMPTIONS'!$B$5:$B$39,0))+MAX(H6-D6*INDEX('01_ASSUMPTIONS'!$J$5:$J$39,MATCH("enterprise_included_studies",'01_ASSUMPTIONS'!$B$5:$B$39,0)),0)*INDEX('01_ASSUMPTIONS'!$J$5:$J$39,MATCH("enterprise_overage_fee",'01_ASSUMPTIONS'!$B$5:$B$39,0)) | L6: =J6+K6 | M6: =I6*INDEX('01_ASSUMPTIONS'!$J$5:$J$39,MATCH("cloud_cost_per_study",'01_ASSUMPTIONS'!$B$5:$B$39,0)) | N6: =I6*INDEX('01_ASSUMPTIONS'!$J$5:$J$39,MATCH("storage_cost_per_study",'01_ASSUMPTIONS'!$B$5:$B$39,0)) | O6: =I6*INDEX('01_ASSUMPTIONS'!$J$5:$J$39,MATCH("ai_processing_cost_per_study",'01_ASSUMPTIONS'!$B$5:$B$39,0)) | P6: =E6*INDEX('01_ASSUMPTIONS'!$J$5:$J$39,MATCH("variable_support_per_customer",'01_ASSUMPTIONS'!$B$5:$B$39,0)) | Q6: =SUM(M6:P6) | R6: =INDEX('01_ASSUMPTIONS'!$J$5:$J$39,MATCH("fixed_infra",'01_ASSUMPTIONS'!$B$5:$B$39,0)) | S6: =INDEX('01_ASSUMPTIONS'!$J$5:$J$39,MATCH("software_maintenance",'01_ASSUMPTIONS'!$B$5:$B$39,0)) | T6: =INDEX('01_ASSUMPTIONS'!$J$5:$J$39,MATCH("base_support",'01_ASSUMPTIONS'!$B$5:$B$39,0)) | U6: =INDEX('01_ASSUMPTIONS'!$J$5:$J$39,MATCH("admin",'01_ASSUMPTIONS'!$B$5:$B$39,0)) | V6: =INDEX('01_ASSUMPTIONS'!$J$5:$J$39,MATCH("commercial_marketing",'01_ASSUMPTIONS'!$B$5:$B$39,0)) | W6: =INDEX('01_ASSUMPTIONS'!$J$5:$J$39,MATCH("other_fixed",'01_ASSUMPTIONS'!$B$5:$B$39,0)) | X6: =SUM(R6:W6) | Y6: =L6-Q6-X6 | Z6: =0 | AA6: =Y6-Z6 | AB6: =1/(1+'01_ASSUMPTIONS'!$E$2)^A6 | AC6: =AA6*AB6 | AD6: =AD5+AA6 | AE6: =IF(Y6>=0,"Yes","No") | AF6: =IF(AD6>=0,"Yes","No")
A7: =6 | B7: =B6*(1-INDEX('01_ASSUMPTIONS'!$J$5:$J$39,MATCH("monthly_churn",'01_ASSUMPTIONS'!$B$5:$B$39,0)))+INDEX('01_ASSUMPTIONS'!$J$5:$J$39,MATCH("starter_monthly_acquisition",'01_ASSUMPTIONS'!$B$5:$B$39,0)) | C7: =C6*(1-INDEX('01_ASSUMPTIONS'!$J$5:$J$39,MATCH("monthly_churn",'01_ASSUMPTIONS'!$B$5:$B$39,0)))+INDEX('01_ASSUMPTIONS'!$J$5:$J$39,MATCH("professional_monthly_acquisition",'01_ASSUMPTIONS'!$B$5:$B$39,0)) | D7: =D6*(1-INDEX('01_ASSUMPTIONS'!$J$5:$J$39,MATCH("monthly_churn",'01_ASSUMPTIONS'!$B$5:$B$39,0)))+INDEX('01_ASSUMPTIONS'!$J$5:$J$39,MATCH("enterprise_monthly_acquisition",'01_ASSUMPTIONS'!$B$5:$B$39,0)) | E7: =SUM(B7:D7) | F7: =B7*INDEX('01_ASSUMPTIONS'!$J$5:$J$39,MATCH("starter_studies_per_customer",'01_ASSUMPTIONS'!$B$5:$B$39,0)) | G7: =C7*INDEX('01_ASSUMPTIONS'!$J$5:$J$39,MATCH("professional_studies_per_customer",'01_ASSUMPTIONS'!$B$5:$B$39,0)) | H7: =D7*INDEX('01_ASSUMPTIONS'!$J$5:$J$39,MATCH("enterprise_studies_per_customer",'01_ASSUMPTIONS'!$B$5:$B$39,0)) | I7: =SUM(F7:H7) | J7: =B7*INDEX('01_ASSUMPTIONS'!$J$5:$J$39,MATCH("starter_fee",'01_ASSUMPTIONS'!$B$5:$B$39,0))+C7*INDEX('01_ASSUMPTIONS'!$J$5:$J$39,MATCH("professional_fee",'01_ASSUMPTIONS'!$B$5:$B$39,0))+D7*INDEX('01_ASSUMPTIONS'!$J$5:$J$39,MATCH("enterprise_fee",'01_ASSUMPTIONS'!$B$5:$B$39,0)) | K7: =MAX(F7-B7*INDEX('01_ASSUMPTIONS'!$J$5:$J$39,MATCH("starter_included_studies",'01_ASSUMPTIONS'!$B$5:$B$39,0)),0)*INDEX('01_ASSUMPTIONS'!$J$5:$J$39,MATCH("starter_overage_fee",'01_ASSUMPTIONS'!$B$5:$B$39,0))+MAX(G7-C7*INDEX('01_ASSUMPTIONS'!$J$5:$J$39,MATCH("professional_included_studies",'01_ASSUMPTIONS'!$B$5:$B$39,0)),0)*INDEX('01_ASSUMPTIONS'!$J$5:$J$39,MATCH("professional_overage_fee",'01_ASSUMPTIONS'!$B$5:$B$39,0))+MAX(H7-D7*INDEX('01_ASSUMPTIONS'!$J$5:$J$39,MATCH("enterprise_included_studies",'01_ASSUMPTIONS'!$B$5:$B$39,0)),0)*INDEX('01_ASSUMPTIONS'!$J$5:$J$39,MATCH("enterprise_overage_fee",'01_ASSUMPTIONS'!$B$5:$B$39,0)) | L7: =J7+K7 | M7: =I7*INDEX('01_ASSUMPTIONS'!$J$5:$J$39,MATCH("cloud_cost_per_study",'01_ASSUMPTIONS'!$B$5:$B$39,0)) | N7: =I7*INDEX('01_ASSUMPTIONS'!$J$5:$J$39,MATCH("storage_cost_per_study",'01_ASSUMPTIONS'!$B$5:$B$39,0)) | O7: =I7*INDEX('01_ASSUMPTIONS'!$J$5:$J$39,MATCH("ai_processing_cost_per_study",'01_ASSUMPTIONS'!$B$5:$B$39,0)) | P7: =E7*INDEX('01_ASSUMPTIONS'!$J$5:$J$39,MATCH("variable_support_per_customer",'01_ASSUMPTIONS'!$B$5:$B$39,0)) | Q7: =SUM(M7:P7) | R7: =INDEX('01_ASSUMPTIONS'!$J$5:$J$39,MATCH("fixed_infra",'01_ASSUMPTIONS'!$B$5:$B$39,0)) | S7: =INDEX('01_ASSUMPTIONS'!$J$5:$J$39,MATCH("software_maintenance",'01_ASSUMPTIONS'!$B$5:$B$39,0)) | T7: =INDEX('01_ASSUMPTIONS'!$J$5:$J$39,MATCH("base_support",'01_ASSUMPTIONS'!$B$5:$B$39,0)) | U7: =INDEX('01_ASSUMPTIONS'!$J$5:$J$39,MATCH("admin",'01_ASSUMPTIONS'!$B$5:$B$39,0)) | V7: =INDEX('01_ASSUMPTIONS'!$J$5:$J$39,MATCH("commercial_marketing",'01_ASSUMPTIONS'!$B$5:$B$39,0)) | W7: =INDEX('01_ASSUMPTIONS'!$J$5:$J$39,MATCH("other_fixed",'01_ASSUMPTIONS'!$B$5:$B$39,0)) | X7: =SUM(R7:W7) | Y7: =L7-Q7-X7 | Z7: =0 | AA7: =Y7-Z7 | AB7: =1/(1+'01_ASSUMPTIONS'!$E$2)^A7 | AC7: =AA7*AB7 | AD7: =AD6+AA7 | AE7: =IF(Y7>=0,"Yes","No") | AF7: =IF(AD7>=0,"Yes","No")
A8: =7 | B8: =B7*(1-INDEX('01_ASSUMPTIONS'!$J$5:$J$39,MATCH("monthly_churn",'01_ASSUMPTIONS'!$B$5:$B$39,0)))+INDEX('01_ASSUMPTIONS'!$J$5:$J$39,MATCH("starter_monthly_acquisition",'01_ASSUMPTIONS'!$B$5:$B$39,0)) | C8: =C7*(1-INDEX('01_ASSUMPTIONS'!$J$5:$J$39,MATCH("monthly_churn",'01_ASSUMPTIONS'!$B$5:$B$39,0)))+INDEX('01_ASSUMPTIONS'!$J$5:$J$39,MATCH("professional_monthly_acquisition",'01_ASSUMPTIONS'!$B$5:$B$39,0)) | D8: =D7*(1-INDEX('01_ASSUMPTIONS'!$J$5:$J$39,MATCH("monthly_churn",'01_ASSUMPTIONS'!$B$5:$B$39,0)))+INDEX('01_ASSUMPTIONS'!$J$5:$J$39,MATCH("enterprise_monthly_acquisition",'01_ASSUMPTIONS'!$B$5:$B$39,0)) | E8: =SUM(B8:D8) | F8: =B8*INDEX('01_ASSUMPTIONS'!$J$5:$J$39,MATCH("starter_studies_per_customer",'01_ASSUMPTIONS'!$B$5:$B$39,0)) | G8: =C8*INDEX('01_ASSUMPTIONS'!$J$5:$J$39,MATCH("professional_studies_per_customer",'01_ASSUMPTIONS'!$B$5:$B$39,0)) | H8: =D8*INDEX('01_ASSUMPTIONS'!$J$5:$J$39,MATCH("enterprise_studies_per_customer",'01_ASSUMPTIONS'!$B$5:$B$39,0)) | I8: =SUM(F8:H8) | J8: =B8*INDEX('01_ASSUMPTIONS'!$J$5:$J$39,MATCH("starter_fee",'01_ASSUMPTIONS'!$B$5:$B$39,0))+C8*INDEX('01_ASSUMPTIONS'!$J$5:$J$39,MATCH("professional_fee",'01_ASSUMPTIONS'!$B$5:$B$39,0))+D8*INDEX('01_ASSUMPTIONS'!$J$5:$J$39,MATCH("enterprise_fee",'01_ASSUMPTIONS'!$B$5:$B$39,0)) | K8: =MAX(F8-B8*INDEX('01_ASSUMPTIONS'!$J$5:$J$39,MATCH("starter_included_studies",'01_ASSUMPTIONS'!$B$5:$B$39,0)),0)*INDEX('01_ASSUMPTIONS'!$J$5:$J$39,MATCH("starter_overage_fee",'01_ASSUMPTIONS'!$B$5:$B$39,0))+MAX(G8-C8*INDEX('01_ASSUMPTIONS'!$J$5:$J$39,MATCH("professional_included_studies",'01_ASSUMPTIONS'!$B$5:$B$39,0)),0)*INDEX('01_ASSUMPTIONS'!$J$5:$J$39,MATCH("professional_overage_fee",'01_ASSUMPTIONS'!$B$5:$B$39,0))+MAX(H8-D8*INDEX('01_ASSUMPTIONS'!$J$5:$J$39,MATCH("enterprise_included_studies",'01_ASSUMPTIONS'!$B$5:$B$39,0)),0)*INDEX('01_ASSUMPTIONS'!$J$5:$J$39,MATCH("enterprise_overage_fee",'01_ASSUMPTIONS'!$B$5:$B$39,0)) | L8: =J8+K8 | M8: =I8*INDEX('01_ASSUMPTIONS'!$J$5:$J$39,MATCH("cloud_cost_per_study",'01_ASSUMPTIONS'!$B$5:$B$39,0)) | N8: =I8*INDEX('01_ASSUMPTIONS'!$J$5:$J$39,MATCH("storage_cost_per_study",'01_ASSUMPTIONS'!$B$5:$B$39,0)) | O8: =I8*INDEX('01_ASSUMPTIONS'!$J$5:$J$39,MATCH("ai_processing_cost_per_study",'01_ASSUMPTIONS'!$B$5:$B$39,0)) | P8: =E8*INDEX('01_ASSUMPTIONS'!$J$5:$J$39,MATCH("variable_support_per_customer",'01_ASSUMPTIONS'!$B$5:$B$39,0)) | Q8: =SUM(M8:P8) | R8: =INDEX('01_ASSUMPTIONS'!$J$5:$J$39,MATCH("fixed_infra",'01_ASSUMPTIONS'!$B$5:$B$39,0)) | S8: =INDEX('01_ASSUMPTIONS'!$J$5:$J$39,MATCH("software_maintenance",'01_ASSUMPTIONS'!$B$5:$B$39,0)) | T8: =INDEX('01_ASSUMPTIONS'!$J$5:$J$39,MATCH("base_support",'01_ASSUMPTIONS'!$B$5:$B$39,0)) | U8: =INDEX('01_ASSUMPTIONS'!$J$5:$J$39,MATCH("admin",'01_ASSUMPTIONS'!$B$5:$B$39,0)) | V8: =INDEX('01_ASSUMPTIONS'!$J$5:$J$39,MATCH("commercial_marketing",'01_ASSUMPTIONS'!$B$5:$B$39,0)) | W8: =INDEX('01_ASSUMPTIONS'!$J$5:$J$39,MATCH("other_fixed",'01_ASSUMPTIONS'!$B$5:$B$39,0)) | X8: =SUM(R8:W8) | Y8: =L8-Q8-X8 | Z8: =0 | AA8: =Y8-Z8 | AB8: =1/(1+'01_ASSUMPTIONS'!$E$2)^A8 | AC8: =AA8*AB8 | AD8: =AD7+AA8 | AE8: =IF(Y8>=0,"Yes","No") | AF8: =IF(AD8>=0,"Yes","No")
A9: =8 | B9: =B8*(1-INDEX('01_ASSUMPTIONS'!$J$5:$J$39,MATCH("monthly_churn",'01_ASSUMPTIONS'!$B$5:$B$39,0)))+INDEX('01_ASSUMPTIONS'!$J$5:$J$39,MATCH("starter_monthly_acquisition",'01_ASSUMPTIONS'!$B$5:$B$39,0)) | C9: =C8*(1-INDEX('01_ASSUMPTIONS'!$J$5:$J$39,MATCH("monthly_churn",'01_ASSUMPTIONS'!$B$5:$B$39,0)))+INDEX('01_ASSUMPTIONS'!$J$5:$J$39,MATCH("professional_monthly_acquisition",'01_ASSUMPTIONS'!$B$5:$B$39,0)) | D9: =D8*(1-INDEX('01_ASSUMPTIONS'!$J$5:$J$39,MATCH("monthly_churn",'01_ASSUMPTIONS'!$B$5:$B$39,0)))+INDEX('01_ASSUMPTIONS'!$J$5:$J$39,MATCH("enterprise_monthly_acquisition",'01_ASSUMPTIONS'!$B$5:$B$39,0)) | E9: =SUM(B9:D9) | F9: =B9*INDEX('01_ASSUMPTIONS'!$J$5:$J$39,MATCH("starter_studies_per_customer",'01_ASSUMPTIONS'!$B$5:$B$39,0)) | G9: =C9*INDEX('01_ASSUMPTIONS'!$J$5:$J$39,MATCH("professional_studies_per_customer",'01_ASSUMPTIONS'!$B$5:$B$39,0)) | H9: =D9*INDEX('01_ASSUMPTIONS'!$J$5:$J$39,MATCH("enterprise_studies_per_customer",'01_ASSUMPTIONS'!$B$5:$B$39,0)) | I9: =SUM(F9:H9) | J9: =B9*INDEX('01_ASSUMPTIONS'!$J$5:$J$39,MATCH("starter_fee",'01_ASSUMPTIONS'!$B$5:$B$39,0))+C9*INDEX('01_ASSUMPTIONS'!$J$5:$J$39,MATCH("professional_fee",'01_ASSUMPTIONS'!$B$5:$B$39,0))+D9*INDEX('01_ASSUMPTIONS'!$J$5:$J$39,MATCH("enterprise_fee",'01_ASSUMPTIONS'!$B$5:$B$39,0)) | K9: =MAX(F9-B9*INDEX('01_ASSUMPTIONS'!$J$5:$J$39,MATCH("starter_included_studies",'01_ASSUMPTIONS'!$B$5:$B$39,0)),0)*INDEX('01_ASSUMPTIONS'!$J$5:$J$39,MATCH("starter_overage_fee",'01_ASSUMPTIONS'!$B$5:$B$39,0))+MAX(G9-C9*INDEX('01_ASSUMPTIONS'!$J$5:$J$39,MATCH("professional_included_studies",'01_ASSUMPTIONS'!$B$5:$B$39,0)),0)*INDEX('01_ASSUMPTIONS'!$J$5:$J$39,MATCH("professional_overage_fee",'01_ASSUMPTIONS'!$B$5:$B$39,0))+MAX(H9-D9*INDEX('01_ASSUMPTIONS'!$J$5:$J$39,MATCH("enterprise_included_studies",'01_ASSUMPTIONS'!$B$5:$B$39,0)),0)*INDEX('01_ASSUMPTIONS'!$J$5:$J$39,MATCH("enterprise_overage_fee",'01_ASSUMPTIONS'!$B$5:$B$39,0)) | L9: =J9+K9 | M9: =I9*INDEX('01_ASSUMPTIONS'!$J$5:$J$39,MATCH("cloud_cost_per_study",'01_ASSUMPTIONS'!$B$5:$B$39,0)) | N9: =I9*INDEX('01_ASSUMPTIONS'!$J$5:$J$39,MATCH("storage_cost_per_study",'01_ASSUMPTIONS'!$B$5:$B$39,0)) | O9: =I9*INDEX('01_ASSUMPTIONS'!$J$5:$J$39,MATCH("ai_processing_cost_per_study",'01_ASSUMPTIONS'!$B$5:$B$39,0)) | P9: =E9*INDEX('01_ASSUMPTIONS'!$J$5:$J$39,MATCH("variable_support_per_customer",'01_ASSUMPTIONS'!$B$5:$B$39,0)) | Q9: =SUM(M9:P9) | R9: =INDEX('01_ASSUMPTIONS'!$J$5:$J$39,MATCH("fixed_infra",'01_ASSUMPTIONS'!$B$5:$B$39,0)) | S9: =INDEX('01_ASSUMPTIONS'!$J$5:$J$39,MATCH("software_maintenance",'01_ASSUMPTIONS'!$B$5:$B$39,0)) | T9: =INDEX('01_ASSUMPTIONS'!$J$5:$J$39,MATCH("base_support",'01_ASSUMPTIONS'!$B$5:$B$39,0)) | U9: =INDEX('01_ASSUMPTIONS'!$J$5:$J$39,MATCH("admin",'01_ASSUMPTIONS'!$B$5:$B$39,0)) | V9: =INDEX('01_ASSUMPTIONS'!$J$5:$J$39,MATCH("commercial_marketing",'01_ASSUMPTIONS'!$B$5:$B$39,0)) | W9: =INDEX('01_ASSUMPTIONS'!$J$5:$J$39,MATCH("other_fixed",'01_ASSUMPTIONS'!$B$5:$B$39,0)) | X9: =SUM(R9:W9) | Y9: =L9-Q9-X9 | Z9: =0 | AA9: =Y9-Z9 | AB9: =1/(1+'01_ASSUMPTIONS'!$E$2)^A9 | AC9: =AA9*AB9 | AD9: =AD8+AA9 | AE9: =IF(Y9>=0,"Yes","No") | AF9: =IF(AD9>=0,"Yes","No")
A10: =9 | B10: =B9*(1-INDEX('01_ASSUMPTIONS'!$J$5:$J$39,MATCH("monthly_churn",'01_ASSUMPTIONS'!$B$5:$B$39,0)))+INDEX('01_ASSUMPTIONS'!$J$5:$J$39,MATCH("starter_monthly_acquisition",'01_ASSUMPTIONS'!$B$5:$B$39,0)) | C10: =C9*(1-INDEX('01_ASSUMPTIONS'!$J$5:$J$39,MATCH("monthly_churn",'01_ASSUMPTIONS'!$B$5:$B$39,0)))+INDEX('01_ASSUMPTIONS'!$J$5:$J$39,MATCH("professional_monthly_acquisition",'01_ASSUMPTIONS'!$B$5:$B$39,0)) | D10: =D9*(1-INDEX('01_ASSUMPTIONS'!$J$5:$J$39,MATCH("monthly_churn",'01_ASSUMPTIONS'!$B$5:$B$39,0)))+INDEX('01_ASSUMPTIONS'!$J$5:$J$39,MATCH("enterprise_monthly_acquisition",'01_ASSUMPTIONS'!$B$5:$B$39,0)) | E10: =SUM(B10:D10) | F10: =B10*INDEX('01_ASSUMPTIONS'!$J$5:$J$39,MATCH("starter_studies_per_customer",'01_ASSUMPTIONS'!$B$5:$B$39,0)) | G10: =C10*INDEX('01_ASSUMPTIONS'!$J$5:$J$39,MATCH("professional_studies_per_customer",'01_ASSUMPTIONS'!$B$5:$B$39,0)) | H10: =D10*INDEX('01_ASSUMPTIONS'!$J$5:$J$39,MATCH("enterprise_studies_per_customer",'01_ASSUMPTIONS'!$B$5:$B$39,0)) | I10: =SUM(F10:H10) | J10: =B10*INDEX('01_ASSUMPTIONS'!$J$5:$J$39,MATCH("starter_fee",'01_ASSUMPTIONS'!$B$5:$B$39,0))+C10*INDEX('01_ASSUMPTIONS'!$J$5:$J$39,MATCH("professional_fee",'01_ASSUMPTIONS'!$B$5:$B$39,0))+D10*INDEX('01_ASSUMPTIONS'!$J$5:$J$39,MATCH("enterprise_fee",'01_ASSUMPTIONS'!$B$5:$B$39,0)) | K10: =MAX(F10-B10*INDEX('01_ASSUMPTIONS'!$J$5:$J$39,MATCH("starter_included_studies",'01_ASSUMPTIONS'!$B$5:$B$39,0)),0)*INDEX('01_ASSUMPTIONS'!$J$5:$J$39,MATCH("starter_overage_fee",'01_ASSUMPTIONS'!$B$5:$B$39,0))+MAX(G10-C10*INDEX('01_ASSUMPTIONS'!$J$5:$J$39,MATCH("professional_included_studies",'01_ASSUMPTIONS'!$B$5:$B$39,0)),0)*INDEX('01_ASSUMPTIONS'!$J$5:$J$39,MATCH("professional_overage_fee",'01_ASSUMPTIONS'!$B$5:$B$39,0))+MAX(H10-D10*INDEX('01_ASSUMPTIONS'!$J$5:$J$39,MATCH("enterprise_included_studies",'01_ASSUMPTIONS'!$B$5:$B$39,0)),0)*INDEX('01_ASSUMPTIONS'!$J$5:$J$39,MATCH("enterprise_overage_fee",'01_ASSUMPTIONS'!$B$5:$B$39,0)) | L10: =J10+K10 | M10: =I10*INDEX('01_ASSUMPTIONS'!$J$5:$J$39,MATCH("cloud_cost_per_study",'01_ASSUMPTIONS'!$B$5:$B$39,0)) | N10: =I10*INDEX('01_ASSUMPTIONS'!$J$5:$J$39,MATCH("storage_cost_per_study",'01_ASSUMPTIONS'!$B$5:$B$39,0)) | O10: =I10*INDEX('01_ASSUMPTIONS'!$J$5:$J$39,MATCH("ai_processing_cost_per_study",'01_ASSUMPTIONS'!$B$5:$B$39,0)) | P10: =E10*INDEX('01_ASSUMPTIONS'!$J$5:$J$39,MATCH("variable_support_per_customer",'01_ASSUMPTIONS'!$B$5:$B$39,0)) | Q10: =SUM(M10:P10) | R10: =INDEX('01_ASSUMPTIONS'!$J$5:$J$39,MATCH("fixed_infra",'01_ASSUMPTIONS'!$B$5:$B$39,0)) | S10: =INDEX('01_ASSUMPTIONS'!$J$5:$J$39,MATCH("software_maintenance",'01_ASSUMPTIONS'!$B$5:$B$39,0)) | T10: =INDEX('01_ASSUMPTIONS'!$J$5:$J$39,MATCH("base_support",'01_ASSUMPTIONS'!$B$5:$B$39,0)) | U10: =INDEX('01_ASSUMPTIONS'!$J$5:$J$39,MATCH("admin",'01_ASSUMPTIONS'!$B$5:$B$39,0)) | V10: =INDEX('01_ASSUMPTIONS'!$J$5:$J$39,MATCH("commercial_marketing",'01_ASSUMPTIONS'!$B$5:$B$39,0)) | W10: =INDEX('01_ASSUMPTIONS'!$J$5:$J$39,MATCH("other_fixed",'01_ASSUMPTIONS'!$B$5:$B$39,0)) | X10: =SUM(R10:W10) | Y10: =L10-Q10-X10 | Z10: =0 | AA10: =Y10-Z10 | AB10: =1/(1+'01_ASSUMPTIONS'!$E$2)^A10 | AC10: =AA10*AB10 | AD10: =AD9+AA10 | AE10: =IF(Y10>=0,"Yes","No") | AF10: =IF(AD10>=0,"Yes","No")
A11: =10 | B11: =B10*(1-INDEX('01_ASSUMPTIONS'!$J$5:$J$39,MATCH("monthly_churn",'01_ASSUMPTIONS'!$B$5:$B$39,0)))+INDEX('01_ASSUMPTIONS'!$J$5:$J$39,MATCH("starter_monthly_acquisition",'01_ASSUMPTIONS'!$B$5:$B$39,0)) | C11: =C10*(1-INDEX('01_ASSUMPTIONS'!$J$5:$J$39,MATCH("monthly_churn",'01_ASSUMPTIONS'!$B$5:$B$39,0)))+INDEX('01_ASSUMPTIONS'!$J$5:$J$39,MATCH("professional_monthly_acquisition",'01_ASSUMPTIONS'!$B$5:$B$39,0)) | D11: =D10*(1-INDEX('01_ASSUMPTIONS'!$J$5:$J$39,MATCH("monthly_churn",'01_ASSUMPTIONS'!$B$5:$B$39,0)))+INDEX('01_ASSUMPTIONS'!$J$5:$J$39,MATCH("enterprise_monthly_acquisition",'01_ASSUMPTIONS'!$B$5:$B$39,0)) | E11: =SUM(B11:D11) | F11: =B11*INDEX('01_ASSUMPTIONS'!$J$5:$J$39,MATCH("starter_studies_per_customer",'01_ASSUMPTIONS'!$B$5:$B$39,0)) | G11: =C11*INDEX('01_ASSUMPTIONS'!$J$5:$J$39,MATCH("professional_studies_per_customer",'01_ASSUMPTIONS'!$B$5:$B$39,0)) | H11: =D11*INDEX('01_ASSUMPTIONS'!$J$5:$J$39,MATCH("enterprise_studies_per_customer",'01_ASSUMPTIONS'!$B$5:$B$39,0)) | I11: =SUM(F11:H11) | J11: =B11*INDEX('01_ASSUMPTIONS'!$J$5:$J$39,MATCH("starter_fee",'01_ASSUMPTIONS'!$B$5:$B$39,0))+C11*INDEX('01_ASSUMPTIONS'!$J$5:$J$39,MATCH("professional_fee",'01_ASSUMPTIONS'!$B$5:$B$39,0))+D11*INDEX('01_ASSUMPTIONS'!$J$5:$J$39,MATCH("enterprise_fee",'01_ASSUMPTIONS'!$B$5:$B$39,0)) | K11: =MAX(F11-B11*INDEX('01_ASSUMPTIONS'!$J$5:$J$39,MATCH("starter_included_studies",'01_ASSUMPTIONS'!$B$5:$B$39,0)),0)*INDEX('01_ASSUMPTIONS'!$J$5:$J$39,MATCH("starter_overage_fee",'01_ASSUMPTIONS'!$B$5:$B$39,0))+MAX(G11-C11*INDEX('01_ASSUMPTIONS'!$J$5:$J$39,MATCH("professional_included_studies",'01_ASSUMPTIONS'!$B$5:$B$39,0)),0)*INDEX('01_ASSUMPTIONS'!$J$5:$J$39,MATCH("professional_overage_fee",'01_ASSUMPTIONS'!$B$5:$B$39,0))+MAX(H11-D11*INDEX('01_ASSUMPTIONS'!$J$5:$J$39,MATCH("enterprise_included_studies",'01_ASSUMPTIONS'!$B$5:$B$39,0)),0)*INDEX('01_ASSUMPTIONS'!$J$5:$J$39,MATCH("enterprise_overage_fee",'01_ASSUMPTIONS'!$B$5:$B$39,0)) | L11: =J11+K11 | M11: =I11*INDEX('01_ASSUMPTIONS'!$J$5:$J$39,MATCH("cloud_cost_per_study",'01_ASSUMPTIONS'!$B$5:$B$39,0)) | N11: =I11*INDEX('01_ASSUMPTIONS'!$J$5:$J$39,MATCH("storage_cost_per_study",'01_ASSUMPTIONS'!$B$5:$B$39,0)) | O11: =I11*INDEX('01_ASSUMPTIONS'!$J$5:$J$39,MATCH("ai_processing_cost_per_study",'01_ASSUMPTIONS'!$B$5:$B$39,0)) | P11: =E11*INDEX('01_ASSUMPTIONS'!$J$5:$J$39,MATCH("variable_support_per_customer",'01_ASSUMPTIONS'!$B$5:$B$39,0)) | Q11: =SUM(M11:P11) | R11: =INDEX('01_ASSUMPTIONS'!$J$5:$J$39,MATCH("fixed_infra",'01_ASSUMPTIONS'!$B$5:$B$39,0)) | S11: =INDEX('01_ASSUMPTIONS'!$J$5:$J$39,MATCH("software_maintenance",'01_ASSUMPTIONS'!$B$5:$B$39,0)) | T11: =INDEX('01_ASSUMPTIONS'!$J$5:$J$39,MATCH("base_support",'01_ASSUMPTIONS'!$B$5:$B$39,0)) | U11: =INDEX('01_ASSUMPTIONS'!$J$5:$J$39,MATCH("admin",'01_ASSUMPTIONS'!$B$5:$B$39,0)) | V11: =INDEX('01_ASSUMPTIONS'!$J$5:$J$39,MATCH("commercial_marketing",'01_ASSUMPTIONS'!$B$5:$B$39,0)) | W11: =INDEX('01_ASSUMPTIONS'!$J$5:$J$39,MATCH("other_fixed",'01_ASSUMPTIONS'!$B$5:$B$39,0)) | X11: =SUM(R11:W11) | Y11: =L11-Q11-X11 | Z11: =0 | AA11: =Y11-Z11 | AB11: =1/(1+'01_ASSUMPTIONS'!$E$2)^A11 | AC11: =AA11*AB11 | AD11: =AD10+AA11 | AE11: =IF(Y11>=0,"Yes","No") | AF11: =IF(AD11>=0,"Yes","No")
A12: =11 | B12: =B11*(1-INDEX('01_ASSUMPTIONS'!$J$5:$J$39,MATCH("monthly_churn",'01_ASSUMPTIONS'!$B$5:$B$39,0)))+INDEX('01_ASSUMPTIONS'!$J$5:$J$39,MATCH("starter_monthly_acquisition",'01_ASSUMPTIONS'!$B$5:$B$39,0)) | C12: =C11*(1-INDEX('01_ASSUMPTIONS'!$J$5:$J$39,MATCH("monthly_churn",'01_ASSUMPTIONS'!$B$5:$B$39,0)))+INDEX('01_ASSUMPTIONS'!$J$5:$J$39,MATCH("professional_monthly_acquisition",'01_ASSUMPTIONS'!$B$5:$B$39,0)) | D12: =D11*(1-INDEX('01_ASSUMPTIONS'!$J$5:$J$39,MATCH("monthly_churn",'01_ASSUMPTIONS'!$B$5:$B$39,0)))+INDEX('01_ASSUMPTIONS'!$J$5:$J$39,MATCH("enterprise_monthly_acquisition",'01_ASSUMPTIONS'!$B$5:$B$39,0)) | E12: =SUM(B12:D12) | F12: =B12*INDEX('01_ASSUMPTIONS'!$J$5:$J$39,MATCH("starter_studies_per_customer",'01_ASSUMPTIONS'!$B$5:$B$39,0)) | G12: =C12*INDEX('01_ASSUMPTIONS'!$J$5:$J$39,MATCH("professional_studies_per_customer",'01_ASSUMPTIONS'!$B$5:$B$39,0)) | H12: =D12*INDEX('01_ASSUMPTIONS'!$J$5:$J$39,MATCH("enterprise_studies_per_customer",'01_ASSUMPTIONS'!$B$5:$B$39,0)) | I12: =SUM(F12:H12) | J12: =B12*INDEX('01_ASSUMPTIONS'!$J$5:$J$39,MATCH("starter_fee",'01_ASSUMPTIONS'!$B$5:$B$39,0))+C12*INDEX('01_ASSUMPTIONS'!$J$5:$J$39,MATCH("professional_fee",'01_ASSUMPTIONS'!$B$5:$B$39,0))+D12*INDEX('01_ASSUMPTIONS'!$J$5:$J$39,MATCH("enterprise_fee",'01_ASSUMPTIONS'!$B$5:$B$39,0)) | K12: =MAX(F12-B12*INDEX('01_ASSUMPTIONS'!$J$5:$J$39,MATCH("starter_included_studies",'01_ASSUMPTIONS'!$B$5:$B$39,0)),0)*INDEX('01_ASSUMPTIONS'!$J$5:$J$39,MATCH("starter_overage_fee",'01_ASSUMPTIONS'!$B$5:$B$39,0))+MAX(G12-C12*INDEX('01_ASSUMPTIONS'!$J$5:$J$39,MATCH("professional_included_studies",'01_ASSUMPTIONS'!$B$5:$B$39,0)),0)*INDEX('01_ASSUMPTIONS'!$J$5:$J$39,MATCH("professional_overage_fee",'01_ASSUMPTIONS'!$B$5:$B$39,0))+MAX(H12-D12*INDEX('01_ASSUMPTIONS'!$J$5:$J$39,MATCH("enterprise_included_studies",'01_ASSUMPTIONS'!$B$5:$B$39,0)),0)*INDEX('01_ASSUMPTIONS'!$J$5:$J$39,MATCH("enterprise_overage_fee",'01_ASSUMPTIONS'!$B$5:$B$39,0)) | L12: =J12+K12 | M12: =I12*INDEX('01_ASSUMPTIONS'!$J$5:$J$39,MATCH("cloud_cost_per_study",'01_ASSUMPTIONS'!$B$5:$B$39,0)) | N12: =I12*INDEX('01_ASSUMPTIONS'!$J$5:$J$39,MATCH("storage_cost_per_study",'01_ASSUMPTIONS'!$B$5:$B$39,0)) | O12: =I12*INDEX('01_ASSUMPTIONS'!$J$5:$J$39,MATCH("ai_processing_cost_per_study",'01_ASSUMPTIONS'!$B$5:$B$39,0)) | P12: =E12*INDEX('01_ASSUMPTIONS'!$J$5:$J$39,MATCH("variable_support_per_customer",'01_ASSUMPTIONS'!$B$5:$B$39,0)) | Q12: =SUM(M12:P12) | R12: =INDEX('01_ASSUMPTIONS'!$J$5:$J$39,MATCH("fixed_infra",'01_ASSUMPTIONS'!$B$5:$B$39,0)) | S12: =INDEX('01_ASSUMPTIONS'!$J$5:$J$39,MATCH("software_maintenance",'01_ASSUMPTIONS'!$B$5:$B$39,0)) | T12: =INDEX('01_ASSUMPTIONS'!$J$5:$J$39,MATCH("base_support",'01_ASSUMPTIONS'!$B$5:$B$39,0)) | U12: =INDEX('01_ASSUMPTIONS'!$J$5:$J$39,MATCH("admin",'01_ASSUMPTIONS'!$B$5:$B$39,0)) | V12: =INDEX('01_ASSUMPTIONS'!$J$5:$J$39,MATCH("commercial_marketing",'01_ASSUMPTIONS'!$B$5:$B$39,0)) | W12: =INDEX('01_ASSUMPTIONS'!$J$5:$J$39,MATCH("other_fixed",'01_ASSUMPTIONS'!$B$5:$B$39,0)) | X12: =SUM(R12:W12) | Y12: =L12-Q12-X12 | Z12: =0 | AA12: =Y12-Z12 | AB12: =1/(1+'01_ASSUMPTIONS'!$E$2)^A12 | AC12: =AA12*AB12 | AD12: =AD11+AA12 | AE12: =IF(Y12>=0,"Yes","No") | AF12: =IF(AD12>=0,"Yes","No")
A13: =12 | B13: =B12*(1-INDEX('01_ASSUMPTIONS'!$J$5:$J$39,MATCH("monthly_churn",'01_ASSUMPTIONS'!$B$5:$B$39,0)))+INDEX('01_ASSUMPTIONS'!$J$5:$J$39,MATCH("starter_monthly_acquisition",'01_ASSUMPTIONS'!$B$5:$B$39,0)) | C13: =C12*(1-INDEX('01_ASSUMPTIONS'!$J$5:$J$39,MATCH("monthly_churn",'01_ASSUMPTIONS'!$B$5:$B$39,0)))+INDEX('01_ASSUMPTIONS'!$J$5:$J$39,MATCH("professional_monthly_acquisition",'01_ASSUMPTIONS'!$B$5:$B$39,0)) | D13: =D12*(1-INDEX('01_ASSUMPTIONS'!$J$5:$J$39,MATCH("monthly_churn",'01_ASSUMPTIONS'!$B$5:$B$39,0)))+INDEX('01_ASSUMPTIONS'!$J$5:$J$39,MATCH("enterprise_monthly_acquisition",'01_ASSUMPTIONS'!$B$5:$B$39,0)) | E13: =SUM(B13:D13) | F13: =B13*INDEX('01_ASSUMPTIONS'!$J$5:$J$39,MATCH("starter_studies_per_customer",'01_ASSUMPTIONS'!$B$5:$B$39,0)) | G13: =C13*INDEX('01_ASSUMPTIONS'!$J$5:$J$39,MATCH("professional_studies_per_customer",'01_ASSUMPTIONS'!$B$5:$B$39,0)) | H13: =D13*INDEX('01_ASSUMPTIONS'!$J$5:$J$39,MATCH("enterprise_studies_per_customer",'01_ASSUMPTIONS'!$B$5:$B$39,0)) | I13: =SUM(F13:H13) | J13: =B13*INDEX('01_ASSUMPTIONS'!$J$5:$J$39,MATCH("starter_fee",'01_ASSUMPTIONS'!$B$5:$B$39,0))+C13*INDEX('01_ASSUMPTIONS'!$J$5:$J$39,MATCH("professional_fee",'01_ASSUMPTIONS'!$B$5:$B$39,0))+D13*INDEX('01_ASSUMPTIONS'!$J$5:$J$39,MATCH("enterprise_fee",'01_ASSUMPTIONS'!$B$5:$B$39,0)) | K13: =MAX(F13-B13*INDEX('01_ASSUMPTIONS'!$J$5:$J$39,MATCH("starter_included_studies",'01_ASSUMPTIONS'!$B$5:$B$39,0)),0)*INDEX('01_ASSUMPTIONS'!$J$5:$J$39,MATCH("starter_overage_fee",'01_ASSUMPTIONS'!$B$5:$B$39,0))+MAX(G13-C13*INDEX('01_ASSUMPTIONS'!$J$5:$J$39,MATCH("professional_included_studies",'01_ASSUMPTIONS'!$B$5:$B$39,0)),0)*INDEX('01_ASSUMPTIONS'!$J$5:$J$39,MATCH("professional_overage_fee",'01_ASSUMPTIONS'!$B$5:$B$39,0))+MAX(H13-D13*INDEX('01_ASSUMPTIONS'!$J$5:$J$39,MATCH("enterprise_included_studies",'01_ASSUMPTIONS'!$B$5:$B$39,0)),0)*INDEX('01_ASSUMPTIONS'!$J$5:$J$39,MATCH("enterprise_overage_fee",'01_ASSUMPTIONS'!$B$5:$B$39,0)) | L13: =J13+K13 | M13: =I13*INDEX('01_ASSUMPTIONS'!$J$5:$J$39,MATCH("cloud_cost_per_study",'01_ASSUMPTIONS'!$B$5:$B$39,0)) | N13: =I13*INDEX('01_ASSUMPTIONS'!$J$5:$J$39,MATCH("storage_cost_per_study",'01_ASSUMPTIONS'!$B$5:$B$39,0)) | O13: =I13*INDEX('01_ASSUMPTIONS'!$J$5:$J$39,MATCH("ai_processing_cost_per_study",'01_ASSUMPTIONS'!$B$5:$B$39,0)) | P13: =E13*INDEX('01_ASSUMPTIONS'!$J$5:$J$39,MATCH("variable_support_per_customer",'01_ASSUMPTIONS'!$B$5:$B$39,0)) | Q13: =SUM(M13:P13) | R13: =INDEX('01_ASSUMPTIONS'!$J$5:$J$39,MATCH("fixed_infra",'01_ASSUMPTIONS'!$B$5:$B$39,0)) | S13: =INDEX('01_ASSUMPTIONS'!$J$5:$J$39,MATCH("software_maintenance",'01_ASSUMPTIONS'!$B$5:$B$39,0)) | T13: =INDEX('01_ASSUMPTIONS'!$J$5:$J$39,MATCH("base_support",'01_ASSUMPTIONS'!$B$5:$B$39,0)) | U13: =INDEX('01_ASSUMPTIONS'!$J$5:$J$39,MATCH("admin",'01_ASSUMPTIONS'!$B$5:$B$39,0)) | V13: =INDEX('01_ASSUMPTIONS'!$J$5:$J$39,MATCH("commercial_marketing",'01_ASSUMPTIONS'!$B$5:$B$39,0)) | W13: =INDEX('01_ASSUMPTIONS'!$J$5:$J$39,MATCH("other_fixed",'01_ASSUMPTIONS'!$B$5:$B$39,0)) | X13: =SUM(R13:W13) | Y13: =L13-Q13-X13 | Z13: =0 | AA13: =Y13-Z13 | AB13: =1/(1+'01_ASSUMPTIONS'!$E$2)^A13 | AC13: =AA13*AB13 | AD13: =AD12+AA13 | AE13: =IF(Y13>=0,"Yes","No") | AF13: =IF(AD13>=0,"Yes","No")
A14: =13 | B14: =B13*(1-INDEX('01_ASSUMPTIONS'!$J$5:$J$39,MATCH("monthly_churn",'01_ASSUMPTIONS'!$B$5:$B$39,0)))+INDEX('01_ASSUMPTIONS'!$J$5:$J$39,MATCH("starter_monthly_acquisition",'01_ASSUMPTIONS'!$B$5:$B$39,0)) | C14: =C13*(1-INDEX('01_ASSUMPTIONS'!$J$5:$J$39,MATCH("monthly_churn",'01_ASSUMPTIONS'!$B$5:$B$39,0)))+INDEX('01_ASSUMPTIONS'!$J$5:$J$39,MATCH("professional_monthly_acquisition",'01_ASSUMPTIONS'!$B$5:$B$39,0)) | D14: =D13*(1-INDEX('01_ASSUMPTIONS'!$J$5:$J$39,MATCH("monthly_churn",'01_ASSUMPTIONS'!$B$5:$B$39,0)))+INDEX('01_ASSUMPTIONS'!$J$5:$J$39,MATCH("enterprise_monthly_acquisition",'01_ASSUMPTIONS'!$B$5:$B$39,0)) | E14: =SUM(B14:D14) | F14: =B14*INDEX('01_ASSUMPTIONS'!$J$5:$J$39,MATCH("starter_studies_per_customer",'01_ASSUMPTIONS'!$B$5:$B$39,0)) | G14: =C14*INDEX('01_ASSUMPTIONS'!$J$5:$J$39,MATCH("professional_studies_per_customer",'01_ASSUMPTIONS'!$B$5:$B$39,0)) | H14: =D14*INDEX('01_ASSUMPTIONS'!$J$5:$J$39,MATCH("enterprise_studies_per_customer",'01_ASSUMPTIONS'!$B$5:$B$39,0)) | I14: =SUM(F14:H14) | J14: =B14*INDEX('01_ASSUMPTIONS'!$J$5:$J$39,MATCH("starter_fee",'01_ASSUMPTIONS'!$B$5:$B$39,0))+C14*INDEX('01_ASSUMPTIONS'!$J$5:$J$39,MATCH("professional_fee",'01_ASSUMPTIONS'!$B$5:$B$39,0))+D14*INDEX('01_ASSUMPTIONS'!$J$5:$J$39,MATCH("enterprise_fee",'01_ASSUMPTIONS'!$B$5:$B$39,0)) | K14: =MAX(F14-B14*INDEX('01_ASSUMPTIONS'!$J$5:$J$39,MATCH("starter_included_studies",'01_ASSUMPTIONS'!$B$5:$B$39,0)),0)*INDEX('01_ASSUMPTIONS'!$J$5:$J$39,MATCH("starter_overage_fee",'01_ASSUMPTIONS'!$B$5:$B$39,0))+MAX(G14-C14*INDEX('01_ASSUMPTIONS'!$J$5:$J$39,MATCH("professional_included_studies",'01_ASSUMPTIONS'!$B$5:$B$39,0)),0)*INDEX('01_ASSUMPTIONS'!$J$5:$J$39,MATCH("professional_overage_fee",'01_ASSUMPTIONS'!$B$5:$B$39,0))+MAX(H14-D14*INDEX('01_ASSUMPTIONS'!$J$5:$J$39,MATCH("enterprise_included_studies",'01_ASSUMPTIONS'!$B$5:$B$39,0)),0)*INDEX('01_ASSUMPTIONS'!$J$5:$J$39,MATCH("enterprise_overage_fee",'01_ASSUMPTIONS'!$B$5:$B$39,0)) | L14: =J14+K14 | M14: =I14*INDEX('01_ASSUMPTIONS'!$J$5:$J$39,MATCH("cloud_cost_per_study",'01_ASSUMPTIONS'!$B$5:$B$39,0)) | N14: =I14*INDEX('01_ASSUMPTIONS'!$J$5:$J$39,MATCH("storage_cost_per_study",'01_ASSUMPTIONS'!$B$5:$B$39,0)) | O14: =I14*INDEX('01_ASSUMPTIONS'!$J$5:$J$39,MATCH("ai_processing_cost_per_study",'01_ASSUMPTIONS'!$B$5:$B$39,0)) | P14: =E14*INDEX('01_ASSUMPTIONS'!$J$5:$J$39,MATCH("variable_support_per_customer",'01_ASSUMPTIONS'!$B$5:$B$39,0)) | Q14: =SUM(M14:P14) | R14: =INDEX('01_ASSUMPTIONS'!$J$5:$J$39,MATCH("fixed_infra",'01_ASSUMPTIONS'!$B$5:$B$39,0)) | S14: =INDEX('01_ASSUMPTIONS'!$J$5:$J$39,MATCH("software_maintenance",'01_ASSUMPTIONS'!$B$5:$B$39,0)) | T14: =INDEX('01_ASSUMPTIONS'!$J$5:$J$39,MATCH("base_support",'01_ASSUMPTIONS'!$B$5:$B$39,0)) | U14: =INDEX('01_ASSUMPTIONS'!$J$5:$J$39,MATCH("admin",'01_ASSUMPTIONS'!$B$5:$B$39,0)) | V14: =INDEX('01_ASSUMPTIONS'!$J$5:$J$39,MATCH("commercial_marketing",'01_ASSUMPTIONS'!$B$5:$B$39,0)) | W14: =INDEX('01_ASSUMPTIONS'!$J$5:$J$39,MATCH("other_fixed",'01_ASSUMPTIONS'!$B$5:$B$39,0)) | X14: =SUM(R14:W14) | Y14: =L14-Q14-X14 | Z14: =0 | AA14: =Y14-Z14 | AB14: =1/(1+'01_ASSUMPTIONS'!$E$2)^A14 | AC14: =AA14*AB14 | AD14: =AD13+AA14 | AE14: =IF(Y14>=0,"Yes","No") | AF14: =IF(AD14>=0,"Yes","No")
A15: =14 | B15: =B14*(1-INDEX('01_ASSUMPTIONS'!$J$5:$J$39,MATCH("monthly_churn",'01_ASSUMPTIONS'!$B$5:$B$39,0)))+INDEX('01_ASSUMPTIONS'!$J$5:$J$39,MATCH("starter_monthly_acquisition",'01_ASSUMPTIONS'!$B$5:$B$39,0)) | C15: =C14*(1-INDEX('01_ASSUMPTIONS'!$J$5:$J$39,MATCH("monthly_churn",'01_ASSUMPTIONS'!$B$5:$B$39,0)))+INDEX('01_ASSUMPTIONS'!$J$5:$J$39,MATCH("professional_monthly_acquisition",'01_ASSUMPTIONS'!$B$5:$B$39,0)) | D15: =D14*(1-INDEX('01_ASSUMPTIONS'!$J$5:$J$39,MATCH("monthly_churn",'01_ASSUMPTIONS'!$B$5:$B$39,0)))+INDEX('01_ASSUMPTIONS'!$J$5:$J$39,MATCH("enterprise_monthly_acquisition",'01_ASSUMPTIONS'!$B$5:$B$39,0)) | E15: =SUM(B15:D15) | F15: =B15*INDEX('01_ASSUMPTIONS'!$J$5:$J$39,MATCH("starter_studies_per_customer",'01_ASSUMPTIONS'!$B$5:$B$39,0)) | G15: =C15*INDEX('01_ASSUMPTIONS'!$J$5:$J$39,MATCH("professional_studies_per_customer",'01_ASSUMPTIONS'!$B$5:$B$39,0)) | H15: =D15*INDEX('01_ASSUMPTIONS'!$J$5:$J$39,MATCH("enterprise_studies_per_customer",'01_ASSUMPTIONS'!$B$5:$B$39,0)) | I15: =SUM(F15:H15) | J15: =B15*INDEX('01_ASSUMPTIONS'!$J$5:$J$39,MATCH("starter_fee",'01_ASSUMPTIONS'!$B$5:$B$39,0))+C15*INDEX('01_ASSUMPTIONS'!$J$5:$J$39,MATCH("professional_fee",'01_ASSUMPTIONS'!$B$5:$B$39,0))+D15*INDEX('01_ASSUMPTIONS'!$J$5:$J$39,MATCH("enterprise_fee",'01_ASSUMPTIONS'!$B$5:$B$39,0)) | K15: =MAX(F15-B15*INDEX('01_ASSUMPTIONS'!$J$5:$J$39,MATCH("starter_included_studies",'01_ASSUMPTIONS'!$B$5:$B$39,0)),0)*INDEX('01_ASSUMPTIONS'!$J$5:$J$39,MATCH("starter_overage_fee",'01_ASSUMPTIONS'!$B$5:$B$39,0))+MAX(G15-C15*INDEX('01_ASSUMPTIONS'!$J$5:$J$39,MATCH("professional_included_studies",'01_ASSUMPTIONS'!$B$5:$B$39,0)),0)*INDEX('01_ASSUMPTIONS'!$J$5:$J$39,MATCH("professional_overage_fee",'01_ASSUMPTIONS'!$B$5:$B$39,0))+MAX(H15-D15*INDEX('01_ASSUMPTIONS'!$J$5:$J$39,MATCH("enterprise_included_studies",'01_ASSUMPTIONS'!$B$5:$B$39,0)),0)*INDEX('01_ASSUMPTIONS'!$J$5:$J$39,MATCH("enterprise_overage_fee",'01_ASSUMPTIONS'!$B$5:$B$39,0)) | L15: =J15+K15 | M15: =I15*INDEX('01_ASSUMPTIONS'!$J$5:$J$39,MATCH("cloud_cost_per_study",'01_ASSUMPTIONS'!$B$5:$B$39,0)) | N15: =I15*INDEX('01_ASSUMPTIONS'!$J$5:$J$39,MATCH("storage_cost_per_study",'01_ASSUMPTIONS'!$B$5:$B$39,0)) | O15: =I15*INDEX('01_ASSUMPTIONS'!$J$5:$J$39,MATCH("ai_processing_cost_per_study",'01_ASSUMPTIONS'!$B$5:$B$39,0)) | P15: =E15*INDEX('01_ASSUMPTIONS'!$J$5:$J$39,MATCH("variable_support_per_customer",'01_ASSUMPTIONS'!$B$5:$B$39,0)) | Q15: =SUM(M15:P15) | R15: =INDEX('01_ASSUMPTIONS'!$J$5:$J$39,MATCH("fixed_infra",'01_ASSUMPTIONS'!$B$5:$B$39,0)) | S15: =INDEX('01_ASSUMPTIONS'!$J$5:$J$39,MATCH("software_maintenance",'01_ASSUMPTIONS'!$B$5:$B$39,0)) | T15: =INDEX('01_ASSUMPTIONS'!$J$5:$J$39,MATCH("base_support",'01_ASSUMPTIONS'!$B$5:$B$39,0)) | U15: =INDEX('01_ASSUMPTIONS'!$J$5:$J$39,MATCH("admin",'01_ASSUMPTIONS'!$B$5:$B$39,0)) | V15: =INDEX('01_ASSUMPTIONS'!$J$5:$J$39,MATCH("commercial_marketing",'01_ASSUMPTIONS'!$B$5:$B$39,0)) | W15: =INDEX('01_ASSUMPTIONS'!$J$5:$J$39,MATCH("other_fixed",'01_ASSUMPTIONS'!$B$5:$B$39,0)) | X15: =SUM(R15:W15) | Y15: =L15-Q15-X15 | Z15: =0 | AA15: =Y15-Z15 | AB15: =1/(1+'01_ASSUMPTIONS'!$E$2)^A15 | AC15: =AA15*AB15 | AD15: =AD14+AA15 | AE15: =IF(Y15>=0,"Yes","No") | AF15: =IF(AD15>=0,"Yes","No")
A16: =15 | B16: =B15*(1-INDEX('01_ASSUMPTIONS'!$J$5:$J$39,MATCH("monthly_churn",'01_ASSUMPTIONS'!$B$5:$B$39,0)))+INDEX('01_ASSUMPTIONS'!$J$5:$J$39,MATCH("starter_monthly_acquisition",'01_ASSUMPTIONS'!$B$5:$B$39,0)) | C16: =C15*(1-INDEX('01_ASSUMPTIONS'!$J$5:$J$39,MATCH("monthly_churn",'01_ASSUMPTIONS'!$B$5:$B$39,0)))+INDEX('01_ASSUMPTIONS'!$J$5:$J$39,MATCH("professional_monthly_acquisition",'01_ASSUMPTIONS'!$B$5:$B$39,0)) | D16: =D15*(1-INDEX('01_ASSUMPTIONS'!$J$5:$J$39,MATCH("monthly_churn",'01_ASSUMPTIONS'!$B$5:$B$39,0)))+INDEX('01_ASSUMPTIONS'!$J$5:$J$39,MATCH("enterprise_monthly_acquisition",'01_ASSUMPTIONS'!$B$5:$B$39,0)) | E16: =SUM(B16:D16) | F16: =B16*INDEX('01_ASSUMPTIONS'!$J$5:$J$39,MATCH("starter_studies_per_customer",'01_ASSUMPTIONS'!$B$5:$B$39,0)) | G16: =C16*INDEX('01_ASSUMPTIONS'!$J$5:$J$39,MATCH("professional_studies_per_customer",'01_ASSUMPTIONS'!$B$5:$B$39,0)) | H16: =D16*INDEX('01_ASSUMPTIONS'!$J$5:$J$39,MATCH("enterprise_studies_per_customer",'01_ASSUMPTIONS'!$B$5:$B$39,0)) | I16: =SUM(F16:H16) | J16: =B16*INDEX('01_ASSUMPTIONS'!$J$5:$J$39,MATCH("starter_fee",'01_ASSUMPTIONS'!$B$5:$B$39,0))+C16*INDEX('01_ASSUMPTIONS'!$J$5:$J$39,MATCH("professional_fee",'01_ASSUMPTIONS'!$B$5:$B$39,0))+D16*INDEX('01_ASSUMPTIONS'!$J$5:$J$39,MATCH("enterprise_fee",'01_ASSUMPTIONS'!$B$5:$B$39,0)) | K16: =MAX(F16-B16*INDEX('01_ASSUMPTIONS'!$J$5:$J$39,MATCH("starter_included_studies",'01_ASSUMPTIONS'!$B$5:$B$39,0)),0)*INDEX('01_ASSUMPTIONS'!$J$5:$J$39,MATCH("starter_overage_fee",'01_ASSUMPTIONS'!$B$5:$B$39,0))+MAX(G16-C16*INDEX('01_ASSUMPTIONS'!$J$5:$J$39,MATCH("professional_included_studies",'01_ASSUMPTIONS'!$B$5:$B$39,0)),0)*INDEX('01_ASSUMPTIONS'!$J$5:$J$39,MATCH("professional_overage_fee",'01_ASSUMPTIONS'!$B$5:$B$39,0))+MAX(H16-D16*INDEX('01_ASSUMPTIONS'!$J$5:$J$39,MATCH("enterprise_included_studies",'01_ASSUMPTIONS'!$B$5:$B$39,0)),0)*INDEX('01_ASSUMPTIONS'!$J$5:$J$39,MATCH("enterprise_overage_fee",'01_ASSUMPTIONS'!$B$5:$B$39,0)) | L16: =J16+K16 | M16: =I16*INDEX('01_ASSUMPTIONS'!$J$5:$J$39,MATCH("cloud_cost_per_study",'01_ASSUMPTIONS'!$B$5:$B$39,0)) | N16: =I16*INDEX('01_ASSUMPTIONS'!$J$5:$J$39,MATCH("storage_cost_per_study",'01_ASSUMPTIONS'!$B$5:$B$39,0)) | O16: =I16*INDEX('01_ASSUMPTIONS'!$J$5:$J$39,MATCH("ai_processing_cost_per_study",'01_ASSUMPTIONS'!$B$5:$B$39,0)) | P16: =E16*INDEX('01_ASSUMPTIONS'!$J$5:$J$39,MATCH("variable_support_per_customer",'01_ASSUMPTIONS'!$B$5:$B$39,0)) | Q16: =SUM(M16:P16) | R16: =INDEX('01_ASSUMPTIONS'!$J$5:$J$39,MATCH("fixed_infra",'01_ASSUMPTIONS'!$B$5:$B$39,0)) | S16: =INDEX('01_ASSUMPTIONS'!$J$5:$J$39,MATCH("software_maintenance",'01_ASSUMPTIONS'!$B$5:$B$39,0)) | T16: =INDEX('01_ASSUMPTIONS'!$J$5:$J$39,MATCH("base_support",'01_ASSUMPTIONS'!$B$5:$B$39,0)) | U16: =INDEX('01_ASSUMPTIONS'!$J$5:$J$39,MATCH("admin",'01_ASSUMPTIONS'!$B$5:$B$39,0)) | V16: =INDEX('01_ASSUMPTIONS'!$J$5:$J$39,MATCH("commercial_marketing",'01_ASSUMPTIONS'!$B$5:$B$39,0)) | W16: =INDEX('01_ASSUMPTIONS'!$J$5:$J$39,MATCH("other_fixed",'01_ASSUMPTIONS'!$B$5:$B$39,0)) | X16: =SUM(R16:W16) | Y16: =L16-Q16-X16 | Z16: =0 | AA16: =Y16-Z16 | AB16: =1/(1+'01_ASSUMPTIONS'!$E$2)^A16 | AC16: =AA16*AB16 | AD16: =AD15+AA16 | AE16: =IF(Y16>=0,"Yes","No") | AF16: =IF(AD16>=0,"Yes","No")
A17: =16 | B17: =B16*(1-INDEX('01_ASSUMPTIONS'!$J$5:$J$39,MATCH("monthly_churn",'01_ASSUMPTIONS'!$B$5:$B$39,0)))+INDEX('01_ASSUMPTIONS'!$J$5:$J$39,MATCH("starter_monthly_acquisition",'01_ASSUMPTIONS'!$B$5:$B$39,0)) | C17: =C16*(1-INDEX('01_ASSUMPTIONS'!$J$5:$J$39,MATCH("monthly_churn",'01_ASSUMPTIONS'!$B$5:$B$39,0)))+INDEX('01_ASSUMPTIONS'!$J$5:$J$39,MATCH("professional_monthly_acquisition",'01_ASSUMPTIONS'!$B$5:$B$39,0)) | D17: =D16*(1-INDEX('01_ASSUMPTIONS'!$J$5:$J$39,MATCH("monthly_churn",'01_ASSUMPTIONS'!$B$5:$B$39,0)))+INDEX('01_ASSUMPTIONS'!$J$5:$J$39,MATCH("enterprise_monthly_acquisition",'01_ASSUMPTIONS'!$B$5:$B$39,0)) | E17: =SUM(B17:D17) | F17: =B17*INDEX('01_ASSUMPTIONS'!$J$5:$J$39,MATCH("starter_studies_per_customer",'01_ASSUMPTIONS'!$B$5:$B$39,0)) | G17: =C17*INDEX('01_ASSUMPTIONS'!$J$5:$J$39,MATCH("professional_studies_per_customer",'01_ASSUMPTIONS'!$B$5:$B$39,0)) | H17: =D17*INDEX('01_ASSUMPTIONS'!$J$5:$J$39,MATCH("enterprise_studies_per_customer",'01_ASSUMPTIONS'!$B$5:$B$39,0)) | I17: =SUM(F17:H17) | J17: =B17*INDEX('01_ASSUMPTIONS'!$J$5:$J$39,MATCH("starter_fee",'01_ASSUMPTIONS'!$B$5:$B$39,0))+C17*INDEX('01_ASSUMPTIONS'!$J$5:$J$39,MATCH("professional_fee",'01_ASSUMPTIONS'!$B$5:$B$39,0))+D17*INDEX('01_ASSUMPTIONS'!$J$5:$J$39,MATCH("enterprise_fee",'01_ASSUMPTIONS'!$B$5:$B$39,0)) | K17: =MAX(F17-B17*INDEX('01_ASSUMPTIONS'!$J$5:$J$39,MATCH("starter_included_studies",'01_ASSUMPTIONS'!$B$5:$B$39,0)),0)*INDEX('01_ASSUMPTIONS'!$J$5:$J$39,MATCH("starter_overage_fee",'01_ASSUMPTIONS'!$B$5:$B$39,0))+MAX(G17-C17*INDEX('01_ASSUMPTIONS'!$J$5:$J$39,MATCH("professional_included_studies",'01_ASSUMPTIONS'!$B$5:$B$39,0)),0)*INDEX('01_ASSUMPTIONS'!$J$5:$J$39,MATCH("professional_overage_fee",'01_ASSUMPTIONS'!$B$5:$B$39,0))+MAX(H17-D17*INDEX('01_ASSUMPTIONS'!$J$5:$J$39,MATCH("enterprise_included_studies",'01_ASSUMPTIONS'!$B$5:$B$39,0)),0)*INDEX('01_ASSUMPTIONS'!$J$5:$J$39,MATCH("enterprise_overage_fee",'01_ASSUMPTIONS'!$B$5:$B$39,0)) | L17: =J17+K17 | M17: =I17*INDEX('01_ASSUMPTIONS'!$J$5:$J$39,MATCH("cloud_cost_per_study",'01_ASSUMPTIONS'!$B$5:$B$39,0)) | N17: =I17*INDEX('01_ASSUMPTIONS'!$J$5:$J$39,MATCH("storage_cost_per_study",'01_ASSUMPTIONS'!$B$5:$B$39,0)) | O17: =I17*INDEX('01_ASSUMPTIONS'!$J$5:$J$39,MATCH("ai_processing_cost_per_study",'01_ASSUMPTIONS'!$B$5:$B$39,0)) | P17: =E17*INDEX('01_ASSUMPTIONS'!$J$5:$J$39,MATCH("variable_support_per_customer",'01_ASSUMPTIONS'!$B$5:$B$39,0)) | Q17: =SUM(M17:P17) | R17: =INDEX('01_ASSUMPTIONS'!$J$5:$J$39,MATCH("fixed_infra",'01_ASSUMPTIONS'!$B$5:$B$39,0)) | S17: =INDEX('01_ASSUMPTIONS'!$J$5:$J$39,MATCH("software_maintenance",'01_ASSUMPTIONS'!$B$5:$B$39,0)) | T17: =INDEX('01_ASSUMPTIONS'!$J$5:$J$39,MATCH("base_support",'01_ASSUMPTIONS'!$B$5:$B$39,0)) | U17: =INDEX('01_ASSUMPTIONS'!$J$5:$J$39,MATCH("admin",'01_ASSUMPTIONS'!$B$5:$B$39,0)) | V17: =INDEX('01_ASSUMPTIONS'!$J$5:$J$39,MATCH("commercial_marketing",'01_ASSUMPTIONS'!$B$5:$B$39,0)) | W17: =INDEX('01_ASSUMPTIONS'!$J$5:$J$39,MATCH("other_fixed",'01_ASSUMPTIONS'!$B$5:$B$39,0)) | X17: =SUM(R17:W17) | Y17: =L17-Q17-X17 | Z17: =0 | AA17: =Y17-Z17 | AB17: =1/(1+'01_ASSUMPTIONS'!$E$2)^A17 | AC17: =AA17*AB17 | AD17: =AD16+AA17 | AE17: =IF(Y17>=0,"Yes","No") | AF17: =IF(AD17>=0,"Yes","No")
